Unhandled Error
Traceback (most recent call last):
  File "/usr/lib/python2.7/dist-packages/twisted/python/log.py", line 88, in callWithLogger
    return callWithContext({"system": lp}, func, *args, **kw)
  File "/usr/lib/python2.7/dist-packages/twisted/python/log.py", line 73, in callWithContext
    return context.call({ILogContext: newCtx}, func, *args, **kw)
  File "/usr/lib/python2.7/dist-packages/twisted/python/context.py", line 118, in callWithContext
    return self.currentContext().callWithContext(ctx, func, *args, **kw)
  File "/usr/lib/python2.7/dist-packages/twisted/python/context.py", line 81, in callWithContext
    return func(*args,**kw)
--- <exception caught here> ---
  File "/usr/lib/python2.7/dist-packages/twisted/internet/posixbase.py", line 614, in _doReadOrWrite
    why = selectable.doRead()
  File "/usr/lib/python2.7/dist-packages/twisted/internet/tcp.py", line 214, in doRead
    return self._dataReceived(data)
  File "/usr/lib/python2.7/dist-packages/twisted/internet/tcp.py", line 220, in _dataReceived
    rval = self.protocol.dataReceived(data)
  File "/usr/lib/python2.7/dist-packages/twisted/words/protocols/irc.py", line 2848, in dataReceived
    DccFileReceiveBasic.dataReceived(self, data)
  File "/usr/lib/python2.7/dist-packages/twisted/words/protocols/irc.py", line 2537, in dataReceived
    self.transport.write(struct.pack('!i', self.bytesReceived))
struct.error: integer out of range for 'i' format code

My own logging:
	XDCCFileReceive: <Unconnected DccFileReceive object at 73d29440> closed.  2147486112/2162104320 bytes received (Warning: 14618208 bytes short) and written to 