Unexpected failure from credentials factory
Traceback (most recent call last):
  File "/usr/lib/python2.7/dist-packages/twisted/web/http.py", line 773, in requestReceived
    self.process()
  File "/usr/lib/python2.7/dist-packages/twisted/web/server.py", line 132, in process
    self.render(resrc)
  File "/usr/lib/python2.7/dist-packages/twisted/web/server.py", line 167, in render
    body = resrc.render(self)
  File "/usr/lib/python2.7/dist-packages/twisted/web/_auth/wrapper.py", line 128, in render
    return self._authorizedResource(request).render(request)
--- <exception caught here> ---
  File "/usr/lib/python2.7/dist-packages/twisted/web/_auth/wrapper.py", line 112, in _authorizedResource
    credentials = factory.decode(respString, request)
  File "/usr/lib/python2.7/dist-packages/twisted/web/_auth/digest.py", line 54, in decode
    request.getClientIP())
  File "/usr/lib/python2.7/dist-packages/twisted/cred/credentials.py", line 345, in decode
    for (k, v) in [p.split('=', 1) for p in parts]:
exceptions.ValueError: need more than 1 value to unpack
